Workbook

Sheet Overall
A1: Park-Plus
A2: Month | B2: No. of Transaction | C2: No. of Organisation | D2: No. of Charge Point | E2: Total Consumption(kWh) | F2: Total Amount (with taxes)
A3: 45778 | B3: ='May 25'!A82 -> 79 | C3: ='May 25'!B82 -> 9 | D3: ='May 25'!C82 -> 11 | E3: ='May 25'!D82 -> 542.3 | F3: ='May 25'!E82 -> 11804.95
A4: 45809 | B4: ='June 25'!A187 -> 183 | C4: ='June 25'!B187 -> 6 | D4: ='June 25'!C187 -> 7 | E4: ='June 25'!D187 -> 699.89 | F4: ='June 25'!E187 -> 15378.68
A5: 45839 | B5: ='July 25'!A116 -> 112 | C5: ='July 25'!B116 -> 9 | D5: ='July 25'!C116 -> 11 | E5: ='July 25'!D116 -> 788.751 | F5: ='July 25'!E116 -> 18323.89
A6: 45870 | B6: ='Aug 25'!A77 -> 73 | C6: ='Aug 25'!B77 -> 7 | D6: ='Aug 25'!C77 -> 7 | E6: ='Aug 25'!D77 -> 565.854 | F6: ='Aug 25'!E77 -> 12473.07
A7: 45901 | B7: ='Sep 25'!A266 -> 262 | C7: ='Sep 25'!B266 -> 8 | D7: ='Sep 25'!C266 -> 8 | E7: ='Sep 25'!D266 -> 766.086 | F7: ='Sep 25'!E266 -> 16863.47
A8: 45931 | B8: ='Oct 25'!A225 -> 221 | C8: ='Oct 25'!B225 -> 7 | D8: ='Oct 25'!C225 -> 7 | E8: ='Oct 25'!D225 -> 769.745 | F8: ='Oct 25'!E225 -> 16334.63
A9: 45962 | B9: ='Nov 25'!A451 -> 448 | C9: ='Nov 25'!B451 -> 8 | D9: ='Nov 25'!C451 -> 9 | E9: ='Nov 25'!D451 -> 1066.692 | F9: ='Nov 25'!E451 -> 24190
A10: 45992 | B10: ='Dec 25'!A219 -> 215 | C10: ='Dec 25'!B219 -> 10 | D10: ='Dec 25'!C219 -> 10 | E10: ='Dec 25'!D219 -> 1006.393 | F10: ='Dec 25'!E219 -> 23289.61
A11: 46023 | B11: ='Jan 26'!A143 -> 139 | C11: ='Jan 26'!B143 -> 8 | D11: ='Jan 26'!C143 -> 8 | E11: ='Jan 26'!D143 -> 654.214 | F11: ='Jan 26'!E143 -> 16222.59
A12: 46054 | B12: ='Feb 26'!A701 -> 697 | C12: ='Feb 26'!B701 -> 8 | D12: ='Feb 26'!C701 -> 8 | E12: ='Feb 26'!D701 -> 1139.906 | F12: ='Feb 26'!E701 -> 29161.35
A13: 46082 | B13: ='March 26'!A462 -> 458 | C13: ='March 26'!B462 -> 8 | D13: ='March 26'!C462 -> 8 | E13: ='March 26'!D462 -> 851.528 | F13: ='March 26'!E462 -> 20877.95
A14: 46113 | B14: ='Apr 26'!A198 -> 194 | C14: ='Apr 26'!B198 -> 8 | D14: ='Apr 26'!C198 -> 9 | E14: ='Apr 26'!D198 -> 1218.98 | F14: ='Apr 26'!E198 -> 30163.18
B16: Total | E16: =SUM(E3:E14) -> 10070.339 | F16: =SUM(F3:F14) -> 235083.37

Sheet May 25
A1: Transaction Id | B1: Organisation | C1: Charge Point | D1: Consumption(kWh) | E1: Amount (with taxes)
A2: 155924 | B2: One BKC | C2: goego-mhmu-aa-013 | D2: 0 | E2: 0
A3: 155794 | B3: Mayfair Apartments | C3: goego-gjah-aa-035 | D3: 2.668 | E3: 49.98
A4: 155672 | B4: Hermitage Condominium Association | C4: goego-dncr-aa-047 | D4: 12.923 | E4: 182.99
A5: 155694 | B5: One BKC | C5: goego-mhmu-aa-013 | D5: 12.1 | E5: 300.84
A6: 155683 | B6: One BKC | C6: goego-mhmu-aa-013 | D6: 28.38 | E6: 711.5
A7: 155671 | B7: Hermitage Condominium Association | C7: goego-dncr-aa-047 | D7: 0 | E7: 0
A8: 155334 | B8: Trishla City | C8: goego-pbmo-aa-002 | D8: 11.506 | E8: 277.44
A9: 155315 | B9: Prima Bay | C9: goego-mhmu-aa-036 | D9: 29.01 | E9: 861.69
A10: 155224 | B10: Cessena Business Park | C10: goego-kabn-aa-024 | D10: 0 | E10: 0
A11: 155007 | B11: Pebble Bay Owners Association | C11: goego-kabn-aa-037 | D11: 0.643 | E11: 10.62
A12: 154982 | B12: Pebble Bay Owners Association | C12: goego-kabn-aa-037 | D12: 0.884 | E12: 20.5
A13: 154958 | B13: Sterling Ascentia | C13: goego-kabn-aa-041 | D13: 22.143 | E13: 476.22
... A80: 150748 | B80: Pebble Bay Owners Association | C80: goego-kabn-aa-037 | D80: 0.841 | E80: 19.79
A82: =SUMPRODUCT((A2:A80<>"")/COUNTIF(A2:A80,A2:A80&"")) -> 79 | B82: =SUMPRODUCT((B2:B80<>"")/COUNTIF(B2:B80,B2:B80&"")) -> 9 | C82: =SUMPRODUCT((C2:C80<>"")/COUNTIF(C2:C80,C2:C80&"")) -> 11 | D82: =SUM(D2:D80) -> 542.3 | E82: =SUM(E2:E80) -> 11804.95

Sheet June 25
A1: Transaction Id | B1: Organisation | C1: Charge Point | D1: Consumption(kWh) | E1: Amount (with taxes)
A2: 162526 | B2: Cessena Business Park | C2: goego-kabn-aa-024 | D2: 0 | E2: 0
A3: 162522 | B3: Cessena Business Park | C3: goego-kabn-aa-024 | D3: 0 | E3: 0
A4: 162368 | B4: Hermitage Condominium Association | C4: goego-dncr-aa-047 | D4: 0.074 | E4: 1.22
A5: 162347 | B5: One BKC | C5: goego-mhmu-aa-013 | D5: 40.86 | E5: 1015.89
A6: 162360 | B6: Hermitage Condominium Association | C6: goego-dncr-aa-047 | D6: 1.254 | E6: 17.88
A7: 162355 | B7: Hermitage Condominium Association | C7: goego-dncr-aa-047 | D7: 0.182 | E7: 8.48
A8: 162352 | B8: Hermitage Condominium Association | C8: goego-dncr-aa-047 | D8: 0 | E8: 0
A9: 162351 | B9: Hermitage Condominium Association | C9: goego-dncr-aa-047 | D9: 0 | E9: 0
A10: 161913 | B10: Mayfair Apartments | C10: goego-gjah-aa-035 | D10: 2.41 | E10: 45.71
A11: 161950 | B11: Hermitage Condominium Association | C11: goego-dncr-aa-047 | D11: 0.304 | E11: 10.2
A12: 161891 | B12: Cessena Business Park | C12: goego-kabn-aa-031 | D12: 0.437 | E12: 16.21
A13: 161787 | B13: One BKC | C13: goego-mhmu-aa-013 | D13: 18.68 | E13: 470.33
... A59: 161180 | B59: Hermitage Condominium Association | C59: goego-dncr-aa-047 | D59: 0 | E59: 0
A60: 161168 | B60: Hermitage Condominium Association | C60: goego-dncr-aa-047
A61: 161167 | B61: Hermitage Condominium Association | C61: goego-dncr-aa-047 | D61: 0 | E61: 0
A62: 161124 | B62: One BKC | C62: goego-mhmu-aa-013 | D62: 22.11 | E62: 555.61
A63: 161159 | B63: Hermitage Condominium Association | C63: goego-dncr-aa-047 | D63: 0 | E63: 0
A64: 161158 | B64: Hermitage Condominium Association | C64: goego-dncr-aa-047 | D64: 0 | E64: 0
A65: 161157 | B65: Hermitage Condominium Association | C65: goego-dncr-aa-047 | D65: 0 | E65: 0
A66: 161156 | B66: Hermitage Condominium Association | C66: goego-dncr-aa-047 | D66: 0 | E66: 0
A67: 161154 | B67: Hermitage Condominium Association | C67: goego-dncr-aa-047 | D67: 0 | E67: 0
A68: 161153 | B68: Hermitage Condominium Association | C68: goego-dncr-aa-047 | D68: 0 | E68: 0
A69: 161149 | B69: Hermitage Condominium Association | C69: goego-dncr-aa-047 | D69: 0 | E69: 0
A70: 161147 | B70: Hermitage Condominium Association | C70: goego-dncr-aa-047 | D70: 0 | E70: 0
A71: 161145 | B71: Hermitage Condominium Association | C71: goego-dncr-aa-047 | D71: 0 | E71: 0
A72: 161144 | B72: Hermitage Condominium Association | C72: goego-dncr-aa-047 | D72: 0 | E72: 0
A73: 161143 | B73: One BKC | C73: goego-mhmu-aa-013
A74: 161142 | B74: One BKC | C74: goego-mhmu-aa-013 | D74: 0 | E74: 0
A75: 161140 | B75: Hermitage Condominium Association | C75: goego-dncr-aa-047 | D75: 0 | E75: 0
A76: 161138 | B76: Hermitage Condominium Association | C76: goego-dncr-aa-047 | D76: 0 | E76: 0
A77: 161137 | B77: Hermitage Condominium Association | C77: goego-dncr-aa-047 | D77: 0 | E77: 0
A78: 161136 | B78: Hermitage Condominium Association | C78: goego-dncr-aa-047 | D78: 0 | E78: 0
A79: 161134 | B79: Hermitage Condominium Association | C79: goego-dncr-aa-047 | D79: 0 | E79: 0
A80: 161133 | B80: Hermitage Condominium Association | C80: goego-dncr-aa-047 | D80: 0 | E80: 0
A81: 161132 | B81: Hermitage Condominium Association | C81: goego-dncr-aa-047 | D81: 0 | E81: 0
A82: 161130 | B82: Hermitage Condominium Association | C82: goego-dncr-aa-047 | D82: 0 | E82: 0
A83: 161129 | B83: Hermitage Condominium Association | C83: goego-dncr-aa-047 | D83: 0 | E83: 0
A84: 161122 | B84: One BKC | C84: goego-mhmu-aa-013 | D84: 0.33 | E84: 14.1
A85: 161119 | B85: One BKC | C85: goego-mhmu-aa-013 | D85: 0 | E85: 0
...

Sheet July 25
A1: Transaction Id | B1: Organisation | C1: Charge Point | D1: Consumption(kWh) | E1: Amount (with taxes)
A2: 170412 | B2: Prima Bay | C2: goego-mhmu-aa-036 | D2: 10.06 | E2: 302.67
A3: 170315 | B3: Cessena Business Park | C3: goego-kabn-aa-031 | D3: 2.602 | E3: 67.31
A4: 170314 | B4: Cessena Business Park | C4: goego-kabn-aa-031 | D4: 0 | E4: 0
A5: 170285 | B5: One BKC | C5: goego-mhmu-aa-013 | D5: 35.07 | E5: 871.93
A6: 170233 | B6: Kosmo One | C6: goego-tnch-aa-009 | D6: 0 | E6: 0
A7: 170211 | B7: Kosmo One | C7: goego-tnch-aa-009 | D7: 0 | E7: 0
A8: 170210 | B8: Kosmo One | C8: goego-tnch-aa-009 | D8: 0 | E8: 0
A9: 170174 | B9: Hermitage Condominium Association | C9: goego-dncr-aa-047 | D9: 21.062 | E9: 304.18
A10: 170190 | B10: Cessena Business Park | C10: goego-kabn-aa-031 | D10: 0.676 | E10: 21.85
A11: 169762 | B11: One BKC | C11: goego-mhmu-aa-013 | D11: 4.15 | E11: 109.08
A12: 169697 | B12: Cessena Business Park | C12: goego-kabn-aa-031 | D12: 2.595 | E12: 67.14
A13: 169658 | B13: Mayfair Apartments | C13: goego-gjah-aa-035 | D13: 2.786 | E13: 51.92
... A113: 162597 | B113: One BKC | C113: goego-mhmu-aa-013 | D113: 28.46 | E113: 713.49
A116: =SUMPRODUCT((A2:A113<>"")/COUNTIF(A2:A113,A2:A113&"")) -> 112 | B116: =SUMPRODUCT((B2:B113<>"")/COUNTIF(B2:B113,B2:B113&"")) -> 9 | C116: =SUMPRODUCT((C2:C113<>"")/COUNTIF(C2:C113,C2:C113&"")) -> 11 | D116: =SUM(D2:D113) -> 788.751 | E116: =SUM(E2:E113) -> 18323.89

Sheet Aug 25
A1: Transaction Id | B1: Organisation | C1: Charge Point | D1: Consumption(kWh) | E1: Amount (with taxes)
A2: 178402 | B2: Mayfair Apartments | C2: goego-gjah-aa-035 | D2: 2.986 | E2: 55.23
A3: 178339 | B3: Hermitage Condominium Association | C3: goego-dncr-aa-047 | D3: 1.256 | E3: 17.78
A4: 178280 | B4: Hermitage Condominium Association | C4: goego-dncr-aa-047 | D4: 7.363 | E4: 110.16
A5: 178225 | B5: Cessena Business Park | C5: goego-kabn-aa-031 | D5: 0.182 | E5: 10.2
A6: 178145 | B6: One BKC | C6: goego-mhmu-aa-013 | D6: 7.08 | E6: 176.03
A7: 178137 | B7: One BKC | C7: goego-mhmu-aa-013 | D7: 20.46 | E7: 508.69
A8: 178134 | B8: One BKC | C8: goego-mhmu-aa-013 | D8: 0.29 | E8: 13.11
A9: 178083 | B9: Hermitage Condominium Association | C9: goego-dncr-aa-047 | D9: 20.792 | E9: 300.31
A10: 177537 | B10: Hermitage Condominium Association | C10: goego-dncr-aa-047 | D10: 6.655 | E10: 100.13
A11: 177389 | B11: Hermitage Condominium Association | C11: goego-dncr-aa-047 | D11: 20.78 | E11: 300.14
A12: 177478 | B12: One BKC | C12: goego-mhmu-aa-013 | D12: 40.15 | E12: 1004.13
A13: 177423 | B13: One BKC | C13: goego-mhmu-aa-013 | D13: 2.95 | E13: 73.34
... A74: 170414 | B74: Hermitage Condominium Association | C74: goego-dncr-aa-047 | D74: 27.484 | E74: 389.17
A77: =SUMPRODUCT((A2:A74<>"")/COUNTIF(A2:A74,A2:A74&"")) -> 73 | B77: =SUMPRODUCT((B2:B74<>"")/COUNTIF(B2:B74,B2:B74&"")) -> 7 | C77: =SUMPRODUCT((C2:C74<>"")/COUNTIF(C2:C74,C2:C74&"")) -> 7 | D77: =SUM(D2:D74) -> 565.854 | E77: =SUM(E2:E74) -> 12473.07

Sheet Sep 25
A1: Transaction Id | B1: Organisation | C1: Charge Point | D1: Consumption(kWh) | E1: Amount (with taxes)
A2: 187528 | B2: Mayfair Apartments | C2: goego-gjah-aa-035 | D2: 2.043 | E2: 39.65
A3: 187476 | B3: Cessena Business Park | C3: goego-kabn-aa-031 | D3: 1.87 | E3: 50.03
A4: 187392 | B4: One BKC | C4: goego-mhmu-aa-013 | D4: 0 | E4: 0
A5: 187386 | B5: One BKC | C5: goego-mhmu-aa-013 | D5: 0 | E5: 0
A6: 187385 | B6: One BKC | C6: goego-mhmu-aa-013 | D6: 0 | E6: 0
A7: 187025 | B7: Hermitage Condominium Association | C7: goego-dncr-aa-047 | D7: 18.133 | E7: 262.66
A8: 187032 | B8: Luxuria Estate | C8: goego-upgz-aa-001 | D8: 0 | E8: 0
A9: 187044 | B9: Luxuria Estate | C9: goego-upgz-aa-001 | D9: 0 | E9: 0
A10: 187043 | B10: Luxuria Estate | C10: goego-upgz-aa-001 | D10: 0 | E10: 0
A11: 187042 | B11: Luxuria Estate | C11: goego-upgz-aa-001 | D11: 0 | E11: 0
A12: 187041 | B12: Luxuria Estate | C12: goego-upgz-aa-001 | D12: 0 | E12: 0
A13: 187040 | B13: Luxuria Estate | C13: goego-upgz-aa-001 | D13: 0 | E13: 0
... A263: 178963 | B263: One BKC | C263: goego-mhmu-aa-013 | D263: 32 | E263: 795.6
A266: =SUMPRODUCT((A2:A263<>"")/COUNTIF(A2:A263,A2:A263&"")) -> 262 | B266: =SUMPRODUCT((B2:B263<>"")/COUNTIF(B2:B263,B2:B263&"")) -> 8 | C266: =SUMPRODUCT((C2:C263<>"")/COUNTIF(C2:C263,C2:C263&"")) -> 8 | D266: =SUM(D2:D263) -> 766.086 | E266: =SUM(E2:E263) -> 16863.47

Sheet Oct 25
A1: Transaction Id | B1: Organisation | C1: Charge Point | D1: Consumption(kWh) | E1: Amount (with taxes)
A2: 193746 | B2: One BKC | C2: goego-mhmu-aa-013 | D2: 15.28 | E2: 385.8
A3: 193707 | B3: Cessena Business Park | C3: goego-kabn-aa-031 | D3: 1.023 | E3: 30.04
A4: 193691 | B4: Dhaaruni Residences | C4: goego-kabn-aa-001 | D4: 16.749 | E4: 338.33
A5: 193675 | B5: Luxuria Estate | C5: goego-upgz-aa-001 | D5: 0 | E5: 0
A6: 193680 | B6: Luxuria Estate | C6: goego-upgz-aa-001 | D6: 0 | E6: 0
A7: 193679 | B7: Luxuria Estate | C7: goego-upgz-aa-001 | D7: 0 | E7: 0
A8: 193678 | B8: Luxuria Estate | C8: goego-upgz-aa-001 | D8: 0 | E8: 0
A9: 193677 | B9: Luxuria Estate | C9: goego-upgz-aa-001 | D9: 0 | E9: 0
A10: 193676 | B10: Luxuria Estate | C10: goego-upgz-aa-001 | D10: 0 | E10: 0
A11: 193667 | B11: Luxuria Estate | C11: goego-upgz-aa-001 | D11: 0.966 | E11: 25.07
A12: 193664 | B12: Luxuria Estate | C12: goego-upgz-aa-001 | D12: 0 | E12: 0
A13: 193666 | B13: Luxuria Estate | C13: goego-upgz-aa-001 | D13: 0 | E13: 0
... A222: 187626 | B222: Dhaaruni Residences | C222: goego-kabn-aa-001 | D222: 4.798 | E222: 101.13
A225: =SUMPRODUCT((A2:A222<>"")/COUNTIF(A2:A222,A2:A222&"")) -> 221 | B225: =SUMPRODUCT((B2:B222<>"")/COUNTIF(B2:B222,B2:B222&"")) -> 7 | C225: =SUMPRODUCT((C2:C222<>"")/COUNTIF(C2:C222,C2:C222&"")) -> 7 | D225: =SUM(D2:D222) -> 769.745 | E225: =SUM(E2:E222) -> 16334.63

Sheet Nov 25
A1: Transaction Id | B1: Organisation | C1: Charge Point | D1: Consumption(kWh) | E1: Amount (with taxes)
A2: 202108 | B2: Mayfair Apartments | C2: goego-gjah-aa-035 | D2: 2.25 | E2: 43.07
A3: 202026 | B3: Mayfair Apartments | C3: goego-gjah-aa-035 | D3: 0.251 | E3: 10.05
A4: 202020 | B4: Mayfair Apartments | C4: goego-gjah-aa-035 | D4: 3.155 | E4: 58.02
A5: 201939 | B5: Hermitage Condominium Association | C5: goego-dncr-aa-047 | D5: 13.523 | E5: 197.39
A6: 202000 | B6: Luxuria Estate | C6: goego-upgz-aa-001 | D6: 0 | E6: 0
A7: 202007 | B7: Luxuria Estate | C7: goego-upgz-aa-001 | D7: 0 | E7: 0
A8: 202006 | B8: Luxuria Estate | C8: goego-upgz-aa-001 | D8: 0 | E8: 0
A9: 202005 | B9: Luxuria Estate | C9: goego-upgz-aa-001 | D9: 0 | E9: 5.9
A10: 202004 | B10: Luxuria Estate | C10: goego-upgz-aa-001 | D10: 0 | E10: 5.9
A11: 202003 | B11: Luxuria Estate | C11: goego-upgz-aa-001 | D11: 0 | E11: 0
A12: 202002 | B12: Luxuria Estate | C12: goego-upgz-aa-001 | D12: 0 | E12: 0
A13: 202001 | B13: Luxuria Estate | C13: goego-upgz-aa-001 | D13: 0 | E13: 0
... A449: 193874 | B449: Mayfair Apartments | C449: goego-gjah-aa-035 | D449: 2.533 | E449: 47.75
A451: =SUMPRODUCT((A2:A449<>"")/COUNTIF(A2:A449,A2:A449&"")) -> 448 | B451: =SUMPRODUCT((B2:B449<>"")/COUNTIF(B2:B449,B2:B449&"")) -> 8 | C451: =SUMPRODUCT((C2:C449<>"")/COUNTIF(C2:C449,C2:C449&"")) -> 9 | D451: =SUM(D2:D449) -> 1066.692 | E451: =SUM(E2:E449) -> 24190

Sheet Dec 25
A1: Transaction Id | B1: Organisation | C1: Charge Point | D1: Consumption(kWh) | E1: Amount (with taxes)
A2: 210789 | B2: One BKC | C2: goego-mhmu-aa-013 | D2: 5.27 | E2: 136.93
A3: 210733 | B3: Luxuria Estate | C3: goego-upgz-aa-001 | D3: 1.735 | E3: 40.34
A4: 210657 | B4: Cessena Business Park | C4: goego-kabn-aa-031 | D4: 1.113 | E4: 32.17
A5: 210536 | B5: Trishla City | C5: goego-pbmo-aa-002 | D5: 0.171 | E5: 9.94
A6: 210538 | B6: One BKC | C6: goego-mhmu-aa-013 | D6: 26.46 | E6: 663.76
A7: 209869 | B7: Trishla City | C7: goego-pbmo-aa-002 | D7: 14.975 | E7: 359.31
A8: 209828 | B8: Luxuria Estate | C8: goego-upgz-aa-001 | D8: 2.046 | E8: 46.51
A9: 203182 | B9: Luxuria Estate | C9: goego-upgz-aa-001 | D9: 0.375 | E9: 13.34
A10: 209605 | B10: Mayfair Apartments | C10: goego-gjah-aa-035 | D10: 2.282 | E10: 43.6
A11: 209399 | B11: Cessena Business Park | C11: goego-kabn-aa-031 | D11: 2.4 | E11: 62.54
A12: 209384 | B12: Mayfair Apartments | C12: goego-gjah-aa-035 | D12: 2.854 | E12: 53.05
A13: 209189 | B13: Trishla City | C13: goego-pbmo-aa-002 | D13: 17.329 | E13: 414.86
... A88: 205050 | B88: Hermitage Condominium Association | C88: goego-dncr-aa-047 | D88: 0.494 | E88: 7
A89: 205045 | B89: Hermitage Condominium Association | C89: goego-dncr-aa-047
A90: 205044 | B90: Hermitage Condominium Association | C90: goego-dncr-aa-047 | D90: 0 | E90: 0
A91: 205043 | B91: Hermitage Condominium Association | C91: goego-dncr-aa-047 | D91: 0.019 | E91: 0.27
A92: 205032 | B92: Prima Bay | C92: goego-mhmu-aa-036 | D92: 8.08 | E92: 244.26
A93: 204906 | B93: Mayfair Apartments | C93: goego-gjah-aa-035 | D93: 2.462 | E93: 46.57
A94: 204883 | B94: Luxuria Estate | C94: goego-upgz-aa-001 | D94: 0 | E94: 0
A95: 204888 | B95: Luxuria Estate | C95: goego-upgz-aa-001 | D95: 0 | E95: 0
A96: 204887 | B96: Luxuria Estate | C96: goego-upgz-aa-001 | D96: 0 | E96: 0
A97: 204886 | B97: Luxuria Estate | C97: goego-upgz-aa-001 | D97: 0 | E97: 0
A98: 204885 | B98: Luxuria Estate | C98: goego-upgz-aa-001 | D98: 0 | E98: 0
A99: 204884 | B99: Luxuria Estate | C99: goego-upgz-aa-001 | D99: 0 | E99: 0
A100: 204880 | B100: Luxuria Estate | C100: goego-upgz-aa-001 | D100: 0.093 | E100: 7.75
A101: 204815 | B101: Cessena Business Park | C101: goego-kabn-aa-031 | D101: 1.371 | E101: 38.26
... A216: 202466 | B216: One BKC | C216: goego-mhmu-aa-013 | D216: 21.91 | E216: 550.64
A219: =SUMPRODUCT((A2:A216<>"")/COUNTIF(A2:A216,A2:A216&"")) -> 215 | B219: =SUMPRODUCT((B2:B216<>"")/COUNTIF(B2:B216,B2:B216&"")) -> 10 | C219: =SUMPRODUCT((C2:C216<>"")/COUNTIF(C2:C216,C2:C216&"")) -> 10 | D219: =SUM(D2:D216) -> 1006.393 | E219: =SUM(E2:E216) -> 23289.61

Sheet Jan 26
A1: Transaction Id | B1: Organisation | C1: Charge Point | D1: Consumption(kWh) | E1: Amount (with taxes)
A2: 219030 | B2: Swastik Residency | C2: goego-mhmu-aa-066 | D2: 0 | E2: 0
A3: 208837 | B3: Five Summits | C3: goego-kabn-aa-002 | D3: 1.611 | E3: 30.99
A4: 218652 | B4: Cessena Business Park | C4: goego-kabn-aa-031 | D4: 1.41 | E4: 39.18
A5: 218573 | B5: One BKC | C5: goego-mhmu-aa-013 | D5: 20.53 | E5: 516.33
A6: 218511 | B6: Luxuria Estate | C6: goego-upgz-aa-001 | D6: 0 | E6: 0
A7: 218518 | B7: Luxuria Estate | C7: goego-upgz-aa-001 | D7: 0 | E7: 5.9
A8: 218517 | B8: Luxuria Estate | C8: goego-upgz-aa-001 | D8: 0 | E8: 0
A9: 218515 | B9: Luxuria Estate | C9: goego-upgz-aa-001 | D9: 0 | E9: 0
A10: 218514 | B10: Luxuria Estate | C10: goego-upgz-aa-001 | D10: 0 | E10: 0
A11: 218512 | B11: Luxuria Estate | C11: goego-upgz-aa-001 | D11: 0 | E11: 0
A12: 218509 | B12: Luxuria Estate | C12: goego-upgz-aa-001 | D12: 0 | E12: 0
A13: 218508 | B13: Luxuria Estate | C13: goego-upgz-aa-001 | D13: 0 | E13: 0
... A140: 210914 | B140: One BKC | C140: goego-mhmu-aa-013 | D140: 0 | E140: 0
A143: =SUMPRODUCT((A2:A140<>"")/COUNTIF(A2:A140,A2:A140&"")) -> 139 | B143: =SUMPRODUCT((B2:B140<>"")/COUNTIF(B2:B140,B2:B140&"")) -> 8 | C143: =SUMPRODUCT((C2:C140<>"")/COUNTIF(C2:C140,C2:C140&"")) -> 8 | D143: =SUM(D2:D140) -> 654.214 | E143: =SUM(E2:E140) -> 16222.59

Sheet Feb 26
A1: Transaction Id | B1: Organisation | C1: Charge Point | D1: Consumption(kWh) | E1: Amount (with taxes)
A2: 227713 | B2: Trishla City | C2: goego-pbmo-aa-002 | D2: 14.589 | E2: 350.2
A3: 227473 | B3: Mayfair Apartments | C3: goego-gjah-aa-035 | D3: 2.065 | E3: 40.01
A4: 227500 | B4: Luxuria Estate | C4: goego-upgz-aa-001 | D4: 0 | E4: 0
A5: 227503 | B5: Luxuria Estate | C5: goego-upgz-aa-001 | D5: 0 | E5: 0
A6: 227504 | B6: Luxuria Estate | C6: goego-upgz-aa-001 | D6: 0 | E6: 0
A7: 227502 | B7: Luxuria Estate | C7: goego-upgz-aa-001 | D7: 0 | E7: 0
A8: 227491 | B8: Luxuria Estate | C8: goego-upgz-aa-001 | D8: 0 | E8: 0
A9: 227501 | B9: Luxuria Estate | C9: goego-upgz-aa-001 | D9: 0 | E9: 0
A10: 227499 | B10: Luxuria Estate | C10: goego-upgz-aa-001 | D10: 0 | E10: 0
A11: 227498 | B11: Luxuria Estate | C11: goego-upgz-aa-001 | D11: 0 | E11: 0
A12: 227497 | B12: Luxuria Estate | C12: goego-upgz-aa-001 | D12: 0 | E12: 0
A13: 227496 | B13: Luxuria Estate | C13: goego-upgz-aa-001 | D13: 0 | E13: 0
... A698: 219122 | B698: Mayfair Apartments | C698: goego-gjah-aa-035 | D698: 2.383 | E698: 45.27
A701: =SUMPRODUCT((A2:A698<>"")/COUNTIF(A2:A698,A2:A698&"")) -> 697 | B701: =SUMPRODUCT((B2:B698<>"")/COUNTIF(B2:B698,B2:B698&"")) -> 8 | C701: =SUMPRODUCT((C2:C698<>"")/COUNTIF(C2:C698,C2:C698&"")) -> 8 | D701: =SUM(D2:D698) -> 1139.906 | E701: =SUM(E2:E698) -> 29161.35

Sheet March 26
A1: Transaction Id | B1: Organisation | C1: Charge Point | D1: Consumption(kWh) | E1: Amount (with taxes)
A2: 249789 | B2: One BKC | C2: goego-mhmu-aa-013 | D2: 14.42 | E2: 364.42
A3: 249570 | B3: Mayfair Apartments | C3: goego-gjah-aa-035 | D3: 1.985 | E3: 38.69
A4: 249538 | B4: Trishla City | C4: goego-pbmo-aa-002 | D4: 0 | E4: 0
A5: 249449 | B5: One BKC | C5: goego-mhmu-aa-013 | D5: 23.94 | E5: 601.11
A6: 249271 | B6: Luxuria Estate | C6: goego-upgz-aa-001 | D6: 0 | E6: 0
A7: 249368 | B7: Luxuria Estate | C7: goego-upgz-aa-001 | D7: 0 | E7: 0
A8: 249367 | B8: Luxuria Estate | C8: goego-upgz-aa-001 | D8: 0 | E8: 0
A9: 249366 | B9: Luxuria Estate | C9: goego-upgz-aa-001 | D9: 0 | E9: 0
A10: 249365 | B10: Luxuria Estate | C10: goego-upgz-aa-001 | D10: 0 | E10: 0
A11: 249364 | B11: Luxuria Estate | C11: goego-upgz-aa-001 | D11: 0 | E11: 0
A12: 249363 | B12: Luxuria Estate | C12: goego-upgz-aa-001 | D12: 0 | E12: 0
A13: 249361 | B13: Luxuria Estate | C13: goego-upgz-aa-001 | D13: 0 | E13: 0
... A459: 227792 | B459: Luxuria Estate | C459: goego-upgz-aa-001 | D459: 3.831 | E459: 81.94
A462: =SUMPRODUCT((A2:A459<>"")/COUNTIF(A2:A459,A2:A459&"")) -> 458 | B462: =SUMPRODUCT((B2:B459<>"")/COUNTIF(B2:B459,B2:B459&"")) -> 8 | C462: =SUMPRODUCT((C2:C459<>"")/COUNTIF(C2:C459,C2:C459&"")) -> 8 | D462: =SUM(D2:D459) -> 851.528 | E462: =SUM(E2:E459) -> 20877.95

Sheet Apr 26
A1: Transaction Id | B1: Organisation | C1: Charge Point | D1: Consumption(kWh) | E1: Amount (with taxes)
A2: 273932 | B2: One BKC | C2: goego-mhmu-aa-013 | D2: 22.02 | E2: 553.37
A3: 273898 | B3: Cessena Business Park | C3: goego-kabn-aa-031 | D3: 1.288 | E3: 36.3
A4: 273897 | B4: Cessena Business Park | C4: goego-kabn-aa-031 | D4: 0 | E4: 0
A5: 273880 | B5: One BKC | C5: goego-mhmu-aa-013 | D5: 39.44 | E5: 986.48
A6: 273876 | B6: One BKC | C6: goego-mhmu-aa-013 | D6: 0 | E6: 0
A7: 273874 | B7: One BKC | C7: goego-mhmu-aa-013 | D7: 0 | E7: 0
A8: 273872 | B8: One BKC | C8: goego-mhmu-aa-013 | D8: 0 | E8: 0
A9: 273647 | B9: One BKC | C9: goego-mhmu-aa-013 | D9: 16.81 | E9: 423.84
A10: 273347 | B10: Trishla City | C10: goego-pbmo-aa-003 | D10: 0.005 | E10: 6
A11: 273352 | B11: One BKC | C11: goego-mhmu-aa-013 | D11: 19.32 | E11: 486.25
A12: 273346 | B12: Trishla City | C12: goego-pbmo-aa-003 | D12: 0 | E12: 0
A13: 273344 | B13: Trishla City | C13: goego-pbmo-aa-003 | D13: 0 | E13: 0
... A195: 250373 | B195: Mayfair Apartments | C195: goego-gjah-aa-035 | D195: 0 | E195: 0
A198: =SUMPRODUCT((A2:A195<>"")/COUNTIF(A2:A195,A2:A195&"")) -> 194 | B198: =SUMPRODUCT((B2:B195<>"")/COUNTIF(B2:B195,B2:B195&"")) -> 8 | C198: =SUMPRODUCT((C2:C195<>"")/COUNTIF(C2:C195,C2:C195&"")) -> 9 | D198: =SUM(D2:D195) -> 1218.98 | E198: =SUM(E2:E195) -> 30163.18
